Workbook

Sheet 250725_oplr_r2_rerun_pickorder
A1: campaign_id | B1: seq_id | C1: teselagen_plasmid_id | D1: Sequence Confirmed Glycerol Plate Well | E1: 2505 Sequencing Well | F1: 250725 restreak index | G1: 2507 R2 first try well
A2: AP_OplR | B2: Q12D_Q123D | C2: AP_OplR_R2_0003 | D2: Plate1.A3 | E2: A3 | F2: 1 | G2: =VLOOKUP('250725_oplr_r2_rerun_pickorder'!B2,isaac_plate_layout!$B$1:$E$45,4,FALSE) -> A1
A3: AP_OplR | B3: Q45S_Q123D | C3: AP_OplR_R2_0008 | D3: Plate1.B8 | E3: A8.2 | F3: =F2+1 -> 2 | G3: =VLOOKUP('250725_oplr_r2_rerun_pickorder'!B3,isaac_plate_layout!$B$1:$E$45,4,FALSE) -> D11
A4: AP_OplR | B4: T52G_Y255T | C4: AP_OplR_R2_0009 | D4: Plate1.A9 | E4: A9 | F4: 3 | G4: =VLOOKUP('250725_oplr_r2_rerun_pickorder'!B4,isaac_plate_layout!$B$1:$E$45,4,FALSE) -> A2
A5: AP_OplR | B5: Q63A_E218I | C5: AP_OplR_R2_0010 | D5: Plate1.A10 | E5: A10 | F5: 4 | G5: =VLOOKUP('250725_oplr_r2_rerun_pickorder'!B5,isaac_plate_layout!$B$1:$E$45,4,FALSE) -> A3
A6: AP_OplR | B6: Q63V_Q123D | C6: AP_OplR_R2_0012 | D6: Plate1.A12 | E6: A12 | F6: 5 | G6: =VLOOKUP('250725_oplr_r2_rerun_pickorder'!B6,isaac_plate_layout!$B$1:$E$45,4,FALSE) -> A4
A7: AP_OplR | B7: Q75R_Y255T | C7: AP_OplR_R2_0013 | D7: Plate1.C1 | E7: B1 | F7: 6 | G7: =VLOOKUP('250725_oplr_r2_rerun_pickorder'!B7,isaac_plate_layout!$B$1:$E$45,4,FALSE) -> A5
A8: AP_OplR | B8: F80A_Y255R | C8: AP_OplR_R2_0014 | D8: Plate1.C2 | E8: B2 | F8: 7 | G8: =VLOOKUP('250725_oplr_r2_rerun_pickorder'!B8,isaac_plate_layout!$B$1:$E$45,4,FALSE) -> A6
A9: AP_OplR | B9: Q99R_Q123D | C9: AP_OplR_R2_0015 | D9: Plate1.C3 | E9: B3 | F9: 8 | G9: =VLOOKUP('250725_oplr_r2_rerun_pickorder'!B9,isaac_plate_layout!$B$1:$E$45,4,FALSE) -> A7
A10: AP_OplR | B10: Q123D_Q155S | C10: AP_OplR_R2_0016 | D10: Plate1.D4 | E10: B4.2 | F10: 9 | G10: =VLOOKUP('250725_oplr_r2_rerun_pickorder'!B10,isaac_plate_layout!$B$1:$E$45,4,FALSE) -> D6
A11: AP_OplR | B11: Q123D_A187I | C11: AP_OplR_R2_0018 | D11: Plate1.C6 | E11: B6 | G11: =VLOOKUP('250725_oplr_r2_rerun_pickorder'!B11,isaac_plate_layout!$B$1:$E$45,4,FALSE) -> #N/A
A12: AP_OplR | B12: Q123D_T190L | C12: AP_OplR_R2_0019 | D12: Plate1.C7 | E12: B7 | G12: =VLOOKUP('250725_oplr_r2_rerun_pickorder'!B12,isaac_plate_layout!$B$1:$E$45,4,FALSE) -> #N/A
A13: AP_OplR | B13: Q123D_G237K | C13: AP_OplR_R2_0020 | D13: Plate1.C8 | E13: B8 | F13: 10 | G13: =VLOOKUP('250725_oplr_r2_rerun_pickorder'!B13,isaac_plate_layout!$B$1:$E$45,4,FALSE) -> A8
A14: AP_OplR | B14: Q123D_L241I | C14: AP_OplR_R2_0021 | D14: Plate1.C9 | E14: B9 | F14: 11 | G14: =VLOOKUP('250725_oplr_r2_rerun_pickorder'!B14,isaac_plate_layout!$B$1:$E$45,4,FALSE) -> A9
A15: AP_OplR | B15: Q123D_P254G | C15: AP_OplR_R2_0022 | D15: Plate1.D10 | E15: B10.2 | F15: 12 | G15: =VLOOKUP('250725_oplr_r2_rerun_pickorder'!B15,isaac_plate_layout!$B$1:$E$45,4,FALSE) -> D7
A16: AP_OplR | B16: Q123D_Y255R | C16: AP_OplR_R2_0023 | D16: Plate1.C11 | E16: B11 | F16: 13 | G16: =VLOOKUP('250725_oplr_r2_rerun_pickorder'!B16,isaac_plate_layout!$B$1:$E$45,4,FALSE) -> A10
A17: AP_OplR | B17: Q123D_Q264K | C17: AP_OplR_R2_0024 | D17: Plate1.C12 | E17: B12 | F17: 14 | G17: =VLOOKUP('250725_oplr_r2_rerun_pickorder'!B17,isaac_plate_layout!$B$1:$E$45,4,FALSE) -> A12
A18: AP_OplR | B18: Q123D_Q296H | C18: AP_OplR_R2_0025 | D18: Plate1.E1 | E18: C1 | F18: 15 | G18: =VLOOKUP('250725_oplr_r2_rerun_pickorder'!B18,isaac_plate_layout!$B$1:$E$45,4,FALSE) -> B1
A19: AP_OplR | B19: Q123D_Q303R | C19: AP_OplR_R2_0026 | D19: Plate1.E2 | E19: C2 | F19: 16 | G19: =VLOOKUP('250725_oplr_r2_rerun_pickorder'!B19,isaac_plate_layout!$B$1:$E$45,4,FALSE) -> B2
A20: AP_OplR | B20: Q123D_A309P | C20: AP_OplR_R2_0027 | D20: Plate1.E3 | E20: C3 | F20: 17 | G20: =VLOOKUP('250725_oplr_r2_rerun_pickorder'!B20,isaac_plate_layout!$B$1:$E$45,4,FALSE) -> B3
A21: AP_OplR | B21: Q123D_H318D | C21: AP_OplR_R2_0029 | D21: Plate1.E5 | E21: C5 | G21: =VLOOKUP('250725_oplr_r2_rerun_pickorder'!B21,isaac_plate_layout!$B$1:$E$45,4,FALSE) -> #N/A
A22: AP_OplR | B22: K137A_Y255L | C22: AP_OplR_R2_0030 | D22: Plate1.E6 | E22: C6 | F22: 18 | G22: =VLOOKUP('250725_oplr_r2_rerun_pickorder'!B22,isaac_plate_layout!$B$1:$E$45,4,FALSE) -> B4
A23: AP_OplR | B23: K137P_Y255L | C23: AP_OplR_R2_0031 | D23: Plate1.E7 | E23: C7 | F23: 19 | G23: =VLOOKUP('250725_oplr_r2_rerun_pickorder'!B23,isaac_plate_layout!$B$1:$E$45,4,FALSE) -> B5
A24: AP_OplR | B24: K144A_Y255L | C24: AP_OplR_R2_0033 | D24: Plate1.E9 | E24: C9 | F24: 20 | G24: =VLOOKUP('250725_oplr_r2_rerun_pickorder'!B24,isaac_plate_layout!$B$1:$E$45,4,FALSE) -> B6
A25: AP_OplR | B25: K144A_Y255T | C25: AP_OplR_R2_0034 | D25: Plate1.E10 | E25: C10 | F25: 21 | G25: =VLOOKUP('250725_oplr_r2_rerun_pickorder'!B25,isaac_plate_layout!$B$1:$E$45,4,FALSE) -> B7
A26: AP_OplR | B26: K144D_Y255L | C26: AP_OplR_R2_0035 | D26: Plate1.E11 | E26: C11 | F26: 22 | G26: =VLOOKUP('250725_oplr_r2_rerun_pickorder'!B26,isaac_plate_layout!$B$1:$E$45,4,FALSE) -> B8
A27: AP_OplR | B27: K144E_Y255M | C27: AP_OplR_R2_0038 | D27: Plate1.G2 | E27: D2 | G27: =VLOOKUP('250725_oplr_r2_rerun_pickorder'!B27,isaac_plate_layout!$B$1:$E$45,4,FALSE) -> #N/A
A28: AP_OplR | B28: Y146A_Y255T | C28: AP_OplR_R2_0039 | D28: Plate1.G3 | E28: D3 | F28: 23 | G28: =VLOOKUP('250725_oplr_r2_rerun_pickorder'!B28,isaac_plate_layout!$B$1:$E$45,4,FALSE) -> B10
A29: AP_OplR | B29: Y146C_Y255T | C29: AP_OplR_R2_0040 | D29: Plate1.G4 | E29: D4 | F29: 24 | G29: =VLOOKUP('250725_oplr_r2_rerun_pickorder'!B29,isaac_plate_layout!$B$1:$E$45,4,FALSE) -> B11
A30: AP_OplR | B30: Y146I_Y255T | C30: AP_OplR_R2_0042 | D30: Plate1.G6 | E30: D6 | F30: 25 | G30: =VLOOKUP('250725_oplr_r2_rerun_pickorder'!B30,isaac_plate_layout!$B$1:$E$45,4,FALSE) -> B12
A31: AP_OplR | B31: Y146L_Y255T | C31: AP_OplR_R2_0043 | D31: Plate1.G7 | E31: D7 | F31: 26 | G31: =VLOOKUP('250725_oplr_r2_rerun_pickorder'!B31,isaac_plate_layout!$B$1:$E$45,4,FALSE) -> C1
A32: AP_OplR | B32: Y146S_Y255M | C32: AP_OplR_R2_0045 | D32: Plate1.G9 | E32: D9 | G32: =VLOOKUP('250725_oplr_r2_rerun_pickorder'!B32,isaac_plate_layout!$B$1:$E$45,4,FALSE) -> #N/A
A33: AP_OplR | B33: Y146S_Y255T | C33: AP_OplR_R2_0046 | D33: Plate1.G10 | E33: D10 | G33: =VLOOKUP('250725_oplr_r2_rerun_pickorder'!B33,isaac_plate_layout!$B$1:$E$45,4,FALSE) -> #N/A
A34: AP_OplR | B34: E218I_Y255T | C34: AP_OplR_R2_0050 | D34: Plate2.B2 | E34: E2.2 | F34: 27 | G34: =VLOOKUP('250725_oplr_r2_rerun_pickorder'!B34,isaac_plate_layout!$B$1:$E$45,4,FALSE) -> D9
A35: AP_OplR | B35: E218L_Y255T | C35: AP_OplR_R2_0051 | D35: Plate2.A3 | E35: E3 | F35: 28 | G35: =VLOOKUP('250725_oplr_r2_rerun_pickorder'!B35,isaac_plate_layout!$B$1:$E$45,4,FALSE) -> C4
A36: AP_OplR | B36: E218M_Y255L | C36: AP_OplR_R2_0052 | D36: Plate2.A4 | E36: E4 | G36: =VLOOKUP('250725_oplr_r2_rerun_pickorder'!B36,isaac_plate_layout!$B$1:$E$45,4,FALSE) -> #N/A
A37: AP_OplR | B37: E218R_Y255L | C37: AP_OplR_R2_0053 | D37: Plate2.A5 | E37: E5 | F37: 29 | G37: =VLOOKUP('250725_oplr_r2_rerun_pickorder'!B37,isaac_plate_layout!$B$1:$E$45,4,FALSE) -> C5
A38: AP_OplR | B38: E218R_Y255M | C38: AP_OplR_R2_0054 | D38: Plate2.A6 | E38: E6 | F38: 30 | G38: =VLOOKUP('250725_oplr_r2_rerun_pickorder'!B38,isaac_plate_layout!$B$1:$E$45,4,FALSE) -> C6
A39: AP_OplR | B39: E218R_Y255T | C39: AP_OplR_R2_0055 | D39: Plate2.A7 | E39: E7 | F39: 31 | G39: =VLOOKUP('250725_oplr_r2_rerun_pickorder'!B39,isaac_plate_layout!$B$1:$E$45,4,FALSE) -> C7
A40: AP_OplR | B40: Y220H_Y255M | C40: AP_OplR_R2_0057 | D40: Plate2.A9 | E40: E9 | F40: 32 | G40: =VLOOKUP('250725_oplr_r2_rerun_pickorder'!B40,isaac_plate_layout!$B$1:$E$45,4,FALSE) -> C8
...

Sheet isaac_plate_layout
A1: 1 | B1: Q12D_Q123D | C1: =VLOOKUP(B1,'250725_oplr_r2_rerun_pickorder'!$B$2:$E$49,3,FALSE) -> Plate1.A3 | E1: A1
A2: 2 | B2: T52G_Y255T | C2: =VLOOKUP(B2,'250725_oplr_r2_rerun_pickorder'!$B$2:$E$49,3,FALSE) -> Plate1.A9 | E2: A2
A3: 3 | B3: Q63A_E218I | C3: =VLOOKUP(B3,'250725_oplr_r2_rerun_pickorder'!$B$2:$E$49,3,FALSE) -> Plate1.A10 | E3: A3
A4: 4 | B4: Q63V_Q123D | C4: =VLOOKUP(B4,'250725_oplr_r2_rerun_pickorder'!$B$2:$E$49,3,FALSE) -> Plate1.A12 | E4: A4
A5: 5 | B5: Q75R_Y255T | C5: =VLOOKUP(B5,'250725_oplr_r2_rerun_pickorder'!$B$2:$E$49,3,FALSE) -> Plate1.C1 | E5: A5
A6: 6 | B6: F80A_Y255R | C6: =VLOOKUP(B6,'250725_oplr_r2_rerun_pickorder'!$B$2:$E$49,3,FALSE) -> Plate1.C2 | E6: A6
A7: 7 | B7: Q99R_Q123D | C7: =VLOOKUP(B7,'250725_oplr_r2_rerun_pickorder'!$B$2:$E$49,3,FALSE) -> Plate1.C3 | E7: A7
A8: 8 | B8: Q123D_G237K | C8: =VLOOKUP(B8,'250725_oplr_r2_rerun_pickorder'!$B$2:$E$49,3,FALSE) -> Plate1.C8 | E8: A8
A9: 9 | B9: Q123D_L241I | C9: =VLOOKUP(B9,'250725_oplr_r2_rerun_pickorder'!$B$2:$E$49,3,FALSE) -> Plate1.C9 | E9: A9
A10: 10 | B10: Q123D_Y255R | C10: =VLOOKUP(B10,'250725_oplr_r2_rerun_pickorder'!$B$2:$E$49,3,FALSE) -> Plate1.C11 | E10: A10
A11: 12 | B11: Q123D_Q264K | C11: =VLOOKUP(B11,'250725_oplr_r2_rerun_pickorder'!$B$2:$E$49,3,FALSE) -> Plate1.C12 | E11: A12
A12: 13 | B12: Q123D_Q296H | C12: =VLOOKUP(B12,'250725_oplr_r2_rerun_pickorder'!$B$2:$E$49,3,FALSE) -> Plate1.E1 | E12: B1
... A45: 47 | B45: Q45S_Q123D | C45: =VLOOKUP(B45,'250725_oplr_r2_rerun_pickorder'!$B$2:$E$49,3,FALSE) -> Plate1.B8 | E45: D11
